Workbook

Sheet codebook
A1: Phase | B1: Timestamp | C1: Artifact inspected | D1: Question | E1: Evidence / quote | F1: Initial code | G1: Final code | H1: Theme | I1: Stance
A2: Expectations | B2: 0.00020833333 | C2: n/a | D2: 1 | E2: Ik denk dat ik initieel wel iets van controle zou willen hebben over hoe die precies dingen gaat opstellen. | F2: control over generation | G2: developer control over generation | H2: =_xlfn.XLOOKUP(G2,final_code_definitions!A:A,final_code_definitions!F:F,"") -> Human control and intermediate review | I2: Suggestion
A3: Expectations | B3: 0.00034722222 | C3: n/a | D3: 1 | E3: Het format waarmee je het invoert, daar zal je ook ergens een voorbeeld van moeten geven. | F3: examples as input useful | G3: examples as generation context | H3: =_xlfn.XLOOKUP(G3,final_code_definitions!A:A,final_code_definitions!F:F,"") -> Input quality and project context | I3: Suggestion
A4: Expectations | B4: 0.00048611111 | C4: n/a | D4: 1 | E4: Tussen bedrijven [kan het] heel erg verschillen hoe ze Mendix gebruiken of hoe ze bepaalde dingen opzetten. | F4: company-specific Mendix conventions | G4: project-specific conventions | H4: =_xlfn.XLOOKUP(G4,final_code_definitions!A:A,final_code_definitions!F:F,"") -> Input quality and project context | I4: Conditional
A5: Expectations | B5: 0.00061342593 | C5: n/a | D5: 1 | E5: Als het gewoon in grote lijnen al niet echt overeenkomt met hoe je dingen zou willen zien, dan denk ik dat het snel ophoudt. | F5: high-level fit determines usefulness | G5: high-level fit determines usefulness | H5: =_xlfn.XLOOKUP(G5,final_code_definitions!A:A,final_code_definitions!F:F,"") -> Development handoff and adoption feasibility | I5: Negative
A6: Expectations | B6: 0.00076388889 | C6: n/a | D6: 1 | E6: Misschien dat je iets van voorbeeldapps erin zou kunnen gooien waar hij iets van kan overnemen. | F6: examples as input useful | G6: examples as generation context | H6: =_xlfn.XLOOKUP(G6,final_code_definitions!A:A,final_code_definitions!F:F,"") -> Input quality and project context | I6: Suggestion
A7: Expectations | B7: 0.00076388889 | C7: n/a | D7: 1 | E7: In ieder geval dat je daar iets van context aan kan geven voor datgene wat hij gaat maken | F7: context needed for generation | G7: input context needed for generation | H7: =_xlfn.XLOOKUP(G7,final_code_definitions!A:A,final_code_definitions!F:F,"") -> Input quality and project context | I7: Suggestion
A8: Expectations | B8: 0.0015162037 | C8: n/a | D8: 2 | E8: Ik denk dat je met dingen als masterdata zou gaan beginnen. Alsin echt de core van je processen en je informatie. | F8: master data as starting point | G8: domain model and master data as foundation | H8: =_xlfn.XLOOKUP(G8,final_code_definitions!A:A,final_code_definitions!F:F,"") -> Domain model and data foundation | I8: Positive
A9: Expectations | B9: 0.0015162037 | C9: n/a | D9: 2 | E9: Je [zou] het waarschijnlijk stapsgewijs willen opbouwen. | F9: staged build-up preferred | G9: staged generation preferred | H9: =_xlfn.XLOOKUP(G9,final_code_definitions!A:A,final_code_definitions!F:F,"") -> Process, workflow, and logic quality | I9: Suggestion
A10: Expectations | B10: 0.0015162037 | C10: n/a | D10: 2 | E10: Dat hij dus inderdaad eerst nadenkt over echt de belangrijkste dingen die de basis vormen van je app. | F10: foundational concepts before functionality | G10: domain model and master data as foundation | H10: =_xlfn.XLOOKUP(G10,final_code_definitions!A:A,final_code_definitions!F:F,"") -> Domain model and data foundation | I10: Positive
A11: Expectations | B11: 0.0017824074 | C11: n/a | D11: 2 | E11: En dat hij daarna bijvoorbeeld gaat nadenken over meer specifieke functionaliteiten. | F11: specific functionality after foundation | G11: staged generation preferred | H11: =_xlfn.XLOOKUP(G11,final_code_definitions!A:A,final_code_definitions!F:F,"") -> Process, workflow, and logic quality | I11: Positive
A12: Expectations | B12: 0.0022685185 | C12: n/a | D12: 3 | E12: Dat (masterdata) vormt de basis van de rest van je app. Dat ga je gewoon overal terugzien. | F12: master data as application foundation | G12: domain model and master data as foundation | H12: =_xlfn.XLOOKUP(G12,final_code_definitions!A:A,final_code_definitions!F:F,"") -> Domain model and data foundation | I12: Positive
A13: Expectations | B13: 0.0022685185 | C13: n/a | D13: 3 | E13: Dus dat zou je eerst moeten hebben staan voordat je zomaar met de rest zou beginnen. Daar zit ook een domein model bij, niet zozeer de logica. | F13: master data as application foundation | G13: domain model and master data as foundation | H13: =_xlfn.XLOOKUP(G13,final_code_definitions!A:A,final_code_definitions!F:F,"") -> Domain model and data foundation | I13: Positive
... A17: Expectations | B17: 0.0032986111 | C17: n/a | D17: 3 | E17: Voor een AI [is dat] misschien soms lastig... Het is makkelijker voor een AI om dat apart van elkaar op te zetten omdat je dan minder afhankelijkheden hebt. | F17: AI difficulty with bigger picture | G17: AI struggles with cross-artifact dependencies | H17: =_xlfn.XLOOKUP(G17,final_code_definitions!A:A,final_code_definitions!F:F,"") -> Process, workflow, and logic quality | I17: Conditional
A18: Architecture walkthrough | B18: 0.0051388889 | C18: Inputs | D18: n/a | E18: Wij werken natuurlijk altijd aan de hand van tickets binnen zo'n Scrum methodiek... die zijn altijd meer dan die ene zin. | F18: tickets contain more than user-story sentence | G18: requirements contain more than user-story sentence | H18: =_xlfn.XLOOKUP(G18,final_code_definitions!A:A,final_code_definitions!F:F,"") -> Input quality and project context | I18: Conditional
A19: Architecture walkthrough | B19: 0.0053009259 | C19: Inputs | D19: n/a | E19: Heel fijn dat je het een beetje openhoudt, maar soms is iets van inderdaad acceptatiecriteria ook fijn. | F19: acceptance criteria useful | G19: acceptance criteria support testability | H19: =_xlfn.XLOOKUP(G19,final_code_definitions!A:A,final_code_definitions!F:F,"") -> Input quality and project context | I19: Suggestion
A20: Architecture walkthrough | B20: 0.0054166667 | C20: Inputs | D20: n/a | E20: Als ontwikkelaars kun je het anders ook niet testen, want dan weet je ook niet... je kunt het heel breed interpreteren. | F20: acceptance criteria useful for testing | G20: acceptance criteria support testability | H20: =_xlfn.XLOOKUP(G20,final_code_definitions!A:A,final_code_definitions!F:F,"") -> Input quality and project context | I20: Suggestion
A21: Architecture walkthrough | B21: 0.0054976852 | C21: Inputs | D21: n/a | E21: Ja, en bij de ene klant heb je daar iets meer vrijheid in dan dan bij de andere | F21: customer context affects developer freedom | G21: project-specific interpretation freedom | H21: =_xlfn.XLOOKUP(G21,final_code_definitions!A:A,final_code_definitions!F:F,"") -> Input quality and project context | I21: Conditional
A22: Architecture walkthrough | B22: 0.0054976852 | C22: Inputs | D22: n/a | E22: De kwaliteit van de tickets is echt van heel groot belang voor de kwaliteit van de apps. | F22: ticket quality determines app quality | G22: input quality determines output quality | H22: =_xlfn.XLOOKUP(G22,final_code_definitions!A:A,final_code_definitions!F:F,"") -> Input quality and project context | I22: Positive
A23: Architecture walkthrough | B23: 0.0058680556 | C23: Inputs | D23: n/a | E23: Hoe duidelijker je bent, hoe groter de kans dat je ook echt datgene krijgt wat je wil. | F23: clearer input improves output fit | G23: input specificity reduces interpretation | H23: =_xlfn.XLOOKUP(G23,final_code_definitions!A:A,final_code_definitions!F:F,"") -> Input quality and project context | I23: Positive
A24: Architecture walkthrough | B24: 0.0058680556 | C24: Inputs | D24: n/a | E24: Dan zit er minder interpretatie bij als je dat wat meer afbakent. | F24: clearer scope reduces interpretation | G24: input specificity reduces interpretation | H24: =_xlfn.XLOOKUP(G24,final_code_definitions!A:A,final_code_definitions!F:F,"") -> Input quality and project context | I24: Positive
A25: Architecture walkthrough | B25: 0.0071643519 | C25: PV/VN outputs | D25: 4 | E25: Als ik dit zo zie heb ik niet meteen zoiets van oh, ik weet precies wat ik hiermee kan of moet doen. | F25: PV/VN outputs unclear to developer | G25: intermediate outputs unclear to developer | H25: =_xlfn.XLOOKUP(G25,final_code_definitions!A:A,final_code_definitions!F:F,"") -> Human control and intermediate review | I25: Negative
A26: Architecture walkthrough | B26: 0.0071643519 | C26: PV/VN outputs | D26: 4 | E26: De kracht van low code is ook dat het redelijk intuïtief is. | F26: low-code should remain intuitive | G26: low-code interaction should remain intuitive | H26: =_xlfn.XLOOKUP(G26,final_code_definitions!A:A,final_code_definitions!F:F,"") -> Human control and intermediate review | I26: Conditional
A27: Architecture walkthrough | B27: 0.0075231481 | C27: PV/VN outputs | D27: 4 | E27: Dit op zich niet zou hoeven zien... maar op zich is een controlestap om te verifiëren dat die inderdaad het goed gaat maken waarschijnlijk heel handig. | F27: intermediate validation useful | G27: intermediate validation is useful | H27: =_xlfn.XLOOKUP(G27,final_code_definitions!A:A,final_code_definitions!F:F,"") -> Human control and intermediate review | I27: Positive
A28: Architecture walkthrough | B28: 0.0079282407 | C28: PV/VN outputs | D28: 5 | E28: Ik weet niet precies wat ik hierin zou kunnen aanpassen... wat mijn invloed hier zou kunnen zijn. | F28: review influence unclear | G28: review influence must be clear | H28: =_xlfn.XLOOKUP(G28,final_code_definitions!A:A,final_code_definitions!F:F,"") -> Human control and intermediate review | I28: Negative
A29: Architecture walkthrough | B29: 0.0081018519 | C29: PV/VN outputs | D29: 5 | E29: Ervan uitgaan dat je een hoop richting kan geven, nog meer sturing bovenop wat hier staat, denk ik dat het alleen maar handig is. | F29: developer steering useful | G29: developer steering is useful | H29: =_xlfn.XLOOKUP(G29,final_code_definitions!A:A,final_code_definitions!F:F,"") -> Human control and intermediate review | I29: Positive
A30: Architecture walkthrough | B30: 0.010127315 | C30: Plan | D30: 6 | E30: Wat ik hier zie, spreekt voor mij meer tot de verbeelding dan wat je eerder liet zien. | F30: plan provides understandable review artifact | G30: plan is more understandable than PV/VN outputs | H30: =_xlfn.XLOOKUP(G30,final_code_definitions!A:A,final_code_definitions!F:F,"") -> Human control and intermediate review | I30: Positive
A31: Architecture walkthrough | B31: 0.010127315 | C31: Plan | D31: 6 | E31: Hoe je dat dan zou willen aanpassen is denk ik een volgende vraag, want dit is wel echt een berg aan informatie. | F31: plan provides information overload | G31: plan review can become too complex | H31: =_xlfn.XLOOKUP(G31,final_code_definitions!A:A,final_code_definitions!F:F,"") -> Human control and intermediate review | I31: Negative
A32: Architecture walkthrough | B32: 0.010451389 | C32: Plan | D32: 6 | E32: Het is bijna dat je Mendix aan het nabouwen bent om het allemaal weer te geven. | F32: plan interface risks rebuilding Mendix | G32: plan review can become too complex | H32: =_xlfn.XLOOKUP(G32,final_code_definitions!A:A,final_code_definitions!F:F,"") -> Human control and intermediate review | I32: Negative
A33: Architecture walkthrough | B33: 0.010694444 | C33: Plan | D33: 6 | E33: Ik zie inderdaad ook user roles en module roles staan in het plan. Moet ik daar dan ook dingen in kunnen aanpassen? Als apps groter worden, kan dat wel een hele lijst zijn en ziet het er eigenlijk hetzelfde uit als wanneer je security in je app maakt. | F33: same effort in Mendix as in plan | G33: plan review can become too complex | H33: =_xlfn.XLOOKUP(G33,final_code_definitions!A:A,final_code_definitions!F:F,"") -> Human control and intermediate review | I33: Negative
A34: Architecture walkthrough | B34: 0.011064815 | C34: Plan | D34: 6 | E34: Bij entiteiten en associaties zou je van tevoren veel kunnen aanpassen, bijvoorbeeld dat een entiteit bepaalde informatie bevat die je toch in een andere entiteit wilt hebben, of dat een associatie net iets anders moet. | F34: plan allows corrections | G34: plan supports pre-build correction | H34: =_xlfn.XLOOKUP(G34,final_code_definitions!A:A,final_code_definitions!F:F,"") -> Human control and intermediate review | I34: Negative
A35: Architecture walkthrough | B35: 0.011377315 | C35: Plan | D35: 6 | E35: Als hij bepaalde entiteiten aanmaakt die totaal niet overeenkomen met hoe ik het in mijn hoofd heb, zou ik eerder zeggen: ik doe het gewoon nog eens. Dan gaat het meer om opnieuw prompten. | F35: reprompting preferred for structural mismatch | G35: reprompting preferred for structural mismatch | H35: =_xlfn.XLOOKUP(G35,final_code_definitions!A:A,final_code_definitions!F:F,"") -> Human control and intermediate review | I35: Suggestion
A36: Architecture walkthrough | B36: 0.011643519 | C36: Plan | D36: 6 | E36: Hij heeft bepaalde entiteiten aangemaakt, maar dat is echt totaal niet hoe ik het in mijn hoofd heb. Dan zou je misschien eerder zeggen: ik doe het gewoon nog eens. Het gaat dan meer om het opnieuw prompten. | F36: reprompting preferred for structural mismatch | G36: reprompting preferred for structural mismatch | H36: =_xlfn.XLOOKUP(G36,final_code_definitions!A:A,final_code_definitions!F:F,"") -> Human control and intermediate review | I36: Suggestion
... A45: Architecture walkthrough | B45: 0.014664352 | C45: Plan | D45: 9 | E45: Dan wil je eigenlijk die input nog beter hebben... dan is dat nog belangrijker. | F45: input importance | G45: input specificity reduces interpretation | H45: =_xlfn.XLOOKUP(G45,final_code_definitions!A:A,final_code_definitions!F:F,"") -> Input quality and project context | I45: Negative
A46: Application walkthrough | B46: 0.020023148 | C46: Association | D46: n/a | E46: Meestal letten we er altijd wel op dat associaties leesbaar blijven. Dit kan ik niet echt zien, behalve als ik hem aanklik. | F46: association readability issue | G46: associations and entity links need improvement | H46: =_xlfn.XLOOKUP(G46,final_code_definitions!A:A,final_code_definitions!F:F,"") -> Domain model and data foundation | I46: Negative
A47: Application walkthrough | B47: 0.020428241 | C47: Entity | D47: n/a | E47: Ik zie hier heel veel losse entiteiten staan die niet echt netjes gelinkt zijn | F47: unlinked standalone entities | G47: associations and entity links need improvement | H47: =_xlfn.XLOOKUP(G47,final_code_definitions!A:A,final_code_definitions!F:F,"") -> Domain model and data foundation | I47: Negative
A48: Application walkthrough | B48: 0.020821759 | C48: Entity | D48: n/a | E48: Ik vraag me af of dit de meest efficiënte manier is om deze data op te slaan, want je gaat voor elke entiteit een tabel aanmaken | F48: reuse through enum preferred | G48: entity reuse/generalization preferred | H48: =_xlfn.XLOOKUP(G48,final_code_definitions!A:A,final_code_definitions!F:F,"") -> Domain model and data foundation | I48: Negative
A49: Application walkthrough | B49: 0.020821759 | C49: Entity | D49: n/a | E49: Het concept van hergebruik in Mendix is heel belangrijk. Ik zou het gewoon in één entiteit gooien met iets van een enumwaarde, waardoor je het een stuk kleiner houdt. | F49: reuse through enum preferred | G49: entity reuse/generalization preferred | H49: =_xlfn.XLOOKUP(G49,final_code_definitions!A:A,final_code_definitions!F:F,"") -> Domain model and data foundation | I49: Suggestion
A50: Application walkthrough | B50: 0.021134259 | C50: Domain model | D50: n/a | E50: Als de app groter wordt, kan dit best wel gaan groeien. | F50: reuse through enum preferred | G50: entity reuse/generalization preferred | H50: =_xlfn.XLOOKUP(G50,final_code_definitions!A:A,final_code_definitions!F:F,"") -> Domain model and data foundation | I50: Negative
A51: Application walkthrough | B51: 0.021284722 | C51: Entity | D51: n/a | E51: Omdat het met niks gekoppeld is, is het gewoon plat opslaan van informatie. Dat kun je ook met een enumeration doen. | F51: reuse through enum preferred | G51: entity reuse/generalization preferred | H51: =_xlfn.XLOOKUP(G51,final_code_definitions!A:A,final_code_definitions!F:F,"") -> Domain model and data foundation | I51: Suggestion
...

Sheet questions
A1: ID | B1: Questions
A2: 1 | B2: Wat verwacht jij van een tool die automatisch Mendix-apps kan genereren? Wat is jouw beeld daarbij?
A3: 2 | B3: Wat zou voor jou dan een bruikbaar startpunt zijn?
A4: 3 | B4: Ja, bedoel je daarmee het domeinmodel ook echt al met masterdata?
A5: 4 | B5: PV/VN output nuttig?
A6: 5 | B6: Dus als wij dit bijvoorbeeld in een in een interface hebben (…) dat zou wel nuttig zijn?
A7: 6 | B7: Zie jij hier nut in? In in in zo'n tussenstap waarbij jij nog invloed hebt als als developer?
A8: 7 | B8: Komt dat ook omdat jij als developer gewoon meer ervaring hebt met Mendix waardoor jij dingen sneller weet te vinden bijvoorbeeld?
A9: 8 | B9: Kun je het omschrijven als een chatinterface, vergelijkbaar met ChatGPT, waarmee je heen en weer communiceert met een agent?
A10: 9 | B10: Het genereren duurt lang, op een gehuurde GPU duurde dat 13 minuten ongeveer per per plan.
A11: 10 | B11: Op welke plekken binnen Emixa gebruiken jullie annotaties en documentatie in Mendix?
A12: 11 | B12: Als het system zich niet gaat bemoeien met de inhoud van een Microflow, maar wel een voorzetje voor jou neerzet met de juiste naamconventie en het idee van de flow. En dat je hem dan alleen nog maar zelf hoeft te maken. Want wat zou je daarvan vinden?
A13: 12 | B13: Heb je ook voor elke entiteit een uhm, zo'n new/edit page construct?
... A17: 16 | B17: Heb ik dan nog iets gemist qua wat er echt nodig is om iets in de praktijk bruikbaar te maken?

Sheet final_code_definitions
A1: Code | B1: Definition | C1: Include when | D1: Exclude when | E1: Example quote | F1: Theme
A2: developer control over generation | B2: The expert states that developers need influence over what the generator produces or how generation is steered. | C2: Use when the comment concerns control, steering, or influence over generated output. | D2: Exclude comments only about reviewing finished artifacts without influence. | E2: Ik denk dat ik initieel wel iets van controle zou willen hebben. | F2: Human control and intermediate review
A3: examples as generation context | B3: The expert suggests using example apps, existing projects, or examples as context for generation. | C3: Use when examples/reference apps are proposed as input or guidance. | D3: Exclude generic comments about clearer requirements without examples. | E3: Misschien dat je iets van voorbeeldapps erin zou kunnen gooien. | F3: Input quality and project context
A4: project-specific conventions | B4: The expert notes that practices differ between companies, clients, or projects. | C4: Use when conventions, setup, or expectations vary by organization or project. | D4: Exclude general best-practice comments not tied to context variation. | E4: Tussen bedrijven kan het heel erg verschillen hoe ze Mendix gebruiken. | F4: Input quality and project context
A5: high-level fit determines usefulness | B5: The expert says the generated output is useful only if its broad structure matches developer expectations. | C5: Use when usefulness depends on high-level alignment with expected app structure. | D5: Exclude small corrections or low-level editing comments. | E5: Als het in grote lijnen al niet overeenkomt... dan houdt het snel op. | F5: Development handoff and adoption feasibility
A6: input context needed for generation | B6: The expert says additional context is needed for the generator to produce useful output. | C6: Use when context beyond basic user stories is needed. | D6: Exclude comments specifically about examples, acceptance criteria, or conventions when those are more precise. | E6: Dat je daar iets van context aan kan geven. | F6: Input quality and project context
A7: domain model and master data as foundation | B7: The expert treats master data, data structures, and the domain model as the foundation of the app. | C7: Use when data, master data, entities, relationships, or domain model are described as the starting point. | D7: Exclude comments about specific domain model defects such as missing associations. | E7: Je begint met de data en hoe dat zich tot elkaar verhoudt. | F7: Domain model and data foundation
A8: staged generation preferred | B8: The expert prefers building the application in stages, from foundation to specific functionality. | C8: Use when generation or development should proceed stepwise. | D8: Exclude comments about rerunning or reprompting after failure. | E8: Je zou het waarschijnlijk stapsgewijs willen opbouwen. | F8: Process, workflow, and logic quality
A9: process depends on data model | B9: The expert states that processes require underlying data/master data/domain model structures. | C9: Use when process generation is described as dependent on data structures. | D9: Exclude general statements that the domain model is important. | E9: Je kan niet direct eerst een proces gaan bouwen zonder masterdata. | F9: Domain model and data foundation
A10: AI struggles with cross-artifact dependencies | B10: The expert suggests AI may struggle with dependencies between generated parts or larger conceptual relationships. | C10: Use when AI difficulty is tied to dependencies or separating parts of the app. | D10: Exclude concrete artifact defects such as a wrong flow or missing association. | E10: Voor een AI is dat misschien soms lastig... omdat je dan minder afhankelijkheden hebt. | F10: Process, workflow, and logic quality
A11: requirements contain more than user-story sentence | B11: The expert notes that real tickets/user stories contain more detail than a single user-story sentence. | C11: Use when the comment contrasts minimal user stories with richer real-world tickets. | D11: Exclude comments specifically about acceptance criteria unless that is the main point. | E11: Tickets... zijn altijd meer dan die ene zin. | F11: Input quality and project context
A12: acceptance criteria support testability | B12: The expert says acceptance criteria help clarify expected behavior and enable testing. | C12: Use when acceptance criteria are linked to clarity, interpretation, or testing. | D12: Exclude broader input-quality comments without acceptance criteria. | E12: Als ontwikkelaars kun je het anders ook niet testen. | F12: Input quality and project context
... A59: working artifact demonstrates feasibility | B59: The expert says producing any workable generated app is already a meaningful achievement. | C59: Use for positive feasibility statements about producing a working artifact. | D59: Exclude claims that the output is practically ready. | E59: Dat er überhaupt iets werkbaars uitkomt is al een hele prestatie. | F59: Development handoff and adoption feasibility

Sheet themes
A1: Theme | B1: Description | C1: Codes
A2: Input quality and project context | B2: Observations about the requirements and contextual information needed to generate useful Mendix applications, including tickets, acceptance criteria, examples, customer context, and project-specific conventions. | C2: examples as generation context; input context needed for generation; requirements contain more than user-story sentence; acceptance criteria support testability; project-specific interpretation freedom; input quality determines output quality; input specificity reduces interpretation; project-specific conventions
A3: Human control and intermediate review | B3: Observations about the need for developer control, steering, validation, previewing, and reviewing intermediate outputs before or during generation. | C3: developer control over generation; intermediate outputs unclear to developer; low-code interaction should remain intuitive; intermediate validation is useful; review influence must be clear; developer steering is useful; plan is more understandable than PV/VN outputs; plan review can become too complex; plan supports pre-build correction; reprompting preferred for structural mismatch; fine-grained edits belong in the Modeler; plan useful for high-level review; preview reduces wasted generation time; human oversight remains necessary
A4: Domain model and data foundation | B4: Observations about master data, entities, associations, grouping, reuse, and the role of the domain model as the foundation for the generated application. | C4: domain model and master data as foundation; process depends on data model; associations and entity links need improvement; entity reuse/generalization preferred; domain model grouping could improve
A5: Mendix convention alignment and maintainability | B5: Observations about professional Mendix practices, naming conventions, folder organization, annotations, documentation, traceability, and maintainability of the generated model. | C5: documentation and traceability needed; Mendix naming conventions expected; microflow layout/readability convention followed; folder organization needed for scalability; best practices should guide generation; best-practice correction required
A6: Process, workflow, and logic quality | B6: Observations about microflows, workflows, process behavior, validation logic, Workflow Commons, duplicated logic, and the ability to generate more complex application behavior. | C6: staged generation preferred; AI struggles with cross-artifact dependencies; generated microflow logic incorrect; useful microflow scaffold; workflow concept correctly identified; workflow user assignment partly correct; workflows should be controlled through microflows; workflow is basic but acceptable; Workflow Commons adds practical value; parameterization reduces duplicate flows; validation/decision logic missing; process complexity needs improvement; scaffold usefulness depends on required complexity
A7: Security and access control | B7: Observations about roles, entity access, least-privilege principles, security risks, and whether security should be generated or configured manually. | C7: security is critical for app correctness; direct page actions create security/control risks; least-privilege security needed; security setup remains human-sensitive
A8: Development handoff and adoption feasibility | B8: Observations about whether the generated output is useful as a starting point, the amount of rework needed, whether manual development may be preferable, and the broader feasibility of adopting the pipeline in practice. | C8: high-level fit determines usefulness; page scaffold has limited value; pages should be generated selectively; navigation issues are minor fixes; concept promising but immature; rework threshold determines usefulness; manual building may be preferable to review; working artifact demonstrates feasibility
